<?xml version="1.0" ?>
<testsuite errors="1" failures="0" name="ProjectTests-20200103162843" tests="9" time="76.146">
	<testcase classname="ProjectTests" name="test_auth" time="0.070"/>
	<testcase classname="ProjectTests" name="test_delete" time="0.056"/>
	<testcase classname="ProjectTests" name="test_items" time="0.035"/>
	<testcase classname="ProjectTests" name="test_main_page" time="0.012"/>
	<testcase classname="ProjectTests" name="test_post_resource_doesnot_exist" time="0.153"/>
	<testcase classname="ProjectTests" name="test_put_resource_doesnot_exist" time="0.051"/>
	<testcase classname="ProjectTests" name="test_put_resource_exists" time="0.056"/>
	<testcase classname="ProjectTests" name="test_register" time="0.017"/>
	<testcase classname="ProjectTests" name="test_post_resource_already_exists" time="75.696">
		<error message="" type="AssertionError">
<![CDATA[Traceback (most recent call last):
  File "/Volumes/bruvio128/Dropbox/work/REST-API/flask/section6/code/tests/test.py", line 94, in test_post_resource_already_exists
    assert response.status_code == 400
AssertionError
]]>		</error>
	</testcase>
	<system-out>
<![CDATA[Python 3.5.1 (v3.5.1:37a07cee5969, Dec  5 2015, 21:12:44) 
[GCC 4.2.1 (Apple Inc. build 5666) (dot 3)] on darwin
400
User already registered 
]]>	</system-out>
	<system-err>
<![CDATA[]]>	</system-err>
</testsuite>
